//: [Previous](@previous)

import Foundation

/// Error Handling 错误处理

/// Representing and Throwing Errors 表示并抛出错误

enum VendingMachineError: Error {
    case invalidSelection                    //选择无效
    case insufficientFunds(coinsNeeded: Int) //金额不足
    case outOfStock                          //缺货
}

throw VendingMachineError.insufficientFunds(coinsNeeded: 5)

/// Handling Errors 处理错误
/*
 某个错误被抛出时，附近的某部分代码必须负责处理这个错误，例如纠正这个问题、尝试另外一种方式、或是向用户报告错误。
 
 Swift 中有4种处理错误的方式。你可以把函数抛出的错误传递给调用此函数的代码、用do-catch语句处理错误、将错误作为可选类型处理、或者断言此错误根本不会发生。每种方式在下面的小节中都有描述。
 
 当一个函数抛出一个错误时，你的程序流程会发生改变，所以重要的是你能迅速识别代码中会抛出错误的地方。为了标识出这些地方，在调用一个能抛出错误的函数、方法或者构造器之前，加上try关键字，或者try?或try!这种变体。这些关键字在下面的小节中有具体讲解。
 
 注意
 Swift 中的错误处理和其他语言中用try，catch和throw进行异常处理很像。和其他语言中（包括 Objective-C ）的异常处理不同的是，Swift 中的错误处理并不涉及解除调用栈，这是一个计算代价高昂的过程。就此而言，throw语句的性能特性是可以和return语句相媲美的。
 */


/// Propagating Errors Using Throwing Functions用 throwing 函数传递错误
// 为了表示一个函数、方法或构造器可以抛出错误，在函数声明的参数列表之后加上throws关键字。一个标有throws关键字的函数被称作throwing 函数。如果这个函数指明了返回值类型，throws关键词需要写在箭头（->）的前面。
//func canThrowErrors() throws -> String
//func cannotThrowErrors() -> String

/*
 一个 throwing 函数可以在其内部抛出错误，并将错误传递到函数被调用时的作用域。
 
 注意
 只有 throwing 函数可以传递错误。任何在某个非 throwing 函数内部抛出的错误只能在函数内部处理。
 
 下面的例子中，VendingMachine类有一个vend(itemNamed:)方法，如果请求的物品不存在、缺货或者投入金额小于物品价格，该方法就会抛出一个相应的VendingMachineError：
 */
struct Item {
    var price: Int
    var count: Int
}

class VendingMachine {
    var inventory = [
        "Candy Bar": Item(price: 12, count: 7),
        "Chips": Item(price: 10, count: 4),
        "Pretzels": Item(price: 7, count: 11)
    ]
    var coinsDeposited = 0
    func dispenseSnack(snack: String) {
        print("Dispensing \(snack)")
    }
    
    func vend(itemNamed name: String) throws {
        guard let item = inventory[name] else {
            throw VendingMachineError.invalidSelection
        }
        
        guard item.count > 0 else {
            throw VendingMachineError.outOfStock
        }
        
        guard item.price <= coinsDeposited else {
            throw VendingMachineError.insufficientFunds(coinsNeeded: item.price - coinsDeposited)
        }
        
        coinsDeposited -= item.price
        
        var newItem = item
        newItem.count -= 1
        inventory[name] = newItem
        
        print("Dispensing \(name)")
    }
}

let favoriteSnacks = [
    "Alice": "Chips",
    "Bob": "Licorice",
    "Eve": "Pretzels",
]
func buyFavoriteSnack(person: String, vendingMachine: VendingMachine) throws {
    let snackName = favoriteSnacks[person] ?? "Candy Bar"
    try vendingMachine.vend(itemNamed: snackName)
}
struct PurchasedSnack {
    let name: String
    init(name: String, vendingMachine: VendingMachine) throws {
        try vendingMachine.vend(itemNamed: name)
        self.name = name
    }
}


/// Handling Errors Using Do-Catch 用 Do-Catch 处理错误
/*
 do {
     try expression
     statements
 } catch pattern 1 {
     statements
 } catch pattern 2 where condition {
     statements
 }
 */
var vendingMachine = VendingMachine()
vendingMachine.coinsDeposited = 8
do {
    try buyFavoriteSnack(person: "Alice", vendingMachine: vendingMachine)
} catch VendingMachineError.invalidSelection {
    print("Invalid Selection.")
} catch VendingMachineError.outOfStock {
    print("Out of Stock.")
} catch VendingMachineError.insufficientFunds(let coinsNeeded) {
    print("Insufficient funds. Please insert an additional \(coinsNeeded) coins.")
}
// 打印 “Insufficient funds. Please insert an additional 2 coins.”


/// Converting Errors to Optional Values 将错误转换成可选值
func someThrowingFunction() throws -> Int {
    // ...
}

let x = try? someThrowingFunction()

let y: Int?
do {
    y = try someThrowingFunction()
} catch {
    y = nil
}
/*
 如果someThrowingFunction()抛出一个错误，x和y的值是nil。否则x和y的值就是该函数的返回值。注意，无论someThrowingFunction()的返回值类型是什么类型，x和y都是这个类型的可选类型。例子中此函数返回一个整型，所以x和y是可选整型。
 
 如果你想对所有的错误都采用同样的方式来处理，用try?就可以让你写出简洁的错误处理代码。例如，下面的代码用几种方式来获取数据，如果所有方式都失败了则返回nil。
 */
func fetchData() -> Data? {
    if let data = try? fetchDataFromDisk() { return data }
    if let data = try? fetchDataFromServer() { return data }
    return nil
}


/// Disabling Error Propagation 禁用错误传递
/*
 有时你知道某个throwing函数实际上在运行时是不会抛出错误的，在这种情况下，你可以在表达式前面写try!来禁用错误传递，这会把调用包装在一个不会有错误抛出的运行时断言中。如果真的抛出了错误，你会得到一个运行时错误。
 
 例如，下面的代码使用了loadImage(atPath:)函数，该函数从给定的路径加载图片资源，如果图片无法载入则抛出一个错误。在这种情况下，因为图片是和应用绑定的，运行时不会有错误抛出，所以适合禁用错误传递。
 */
let photo = try! loadImage(atPath: "./Resources/John Appleseed.jpg")


/// Specifying Cleanup Actions 指定清理操作
/*
 可以使用defer语句在即将离开当前代码块时执行一系列语句。该语句让你能执行一些必要的清理工作，不管是以何种方式离开当前代码块的——无论是由于抛出错误而离开，或是由于诸如return、break的语句。例如，你可以用defer语句来确保文件描述符得以关闭，以及手动分配的内存得以释放。
 
 defer语句将代码的执行延迟到当前的作用域退出之前。该语句由defer关键字和要被延迟执行的语句组成。延迟执行的语句不能包含任何控制转移语句，例如break、return语句，或是抛出一个错误。延迟执行的操作会按照它们声明的顺序从后往前执行——也就是说，第一条defer语句中的代码最后才执行，第二条defer语句中的代码倒数第二个执行，以此类推。最后一条语句会第一个执行
 */
func processFile(filename: String) throws {
    if exists(filename) {
        let file = open(filename)
        defer {
            close(file)
        }
        while let line = try file.readline() {
            // 处理文件。
        }
        // close(file) 会在这里被调用，即作用域的最后。
    }
}
/*
 上面的代码使用一条defer语句来确保open(_:)函数有一个相应的对close(_:)函数的调用。
 
 注意
 即使没有涉及到错误处理，你也可以使用defer语句。
 */
